Workbook

Sheet Summary
A1: Nykaa - Descriptive Analytics Summary (Simulated Data)
A2: 30 days | 60 products | 10 categories | 8 cities. Blue = from report, black = formula linked to other sheets.
A4: Metric | B4: Value | C4: Note
A5: Total orders - sum of categories | B5: =Category!B15 -> 6881215 | C5: Report headline says ~6.8M
A6: Total orders - sum of devices | B6: ='Device Mix'!B10 -> 6835047 | C6: Differs slightly from category total
A7: Total GMV (INR Cr) - membership split | B7: =Membership!C7 -> 495.00848 | C7: Report headline: ~Rs. 495 Cr
A8: Total revenue (INR Cr) - category table | B8: =Category!D15 -> 648.38623 | C8: Does NOT match 495 Cr headline - see Notes
A9: Average product rating (out of 5) | B9: 4.01 | C9: Section 5
A10: Top single-day product | B10: Nykaa Cosmetics Face Mist | C10: 34,399 orders
A11: Cities tracked | B11: 8 | C11: Bangalore, Delhi NCR, Mumbai, Hyderabad, Pune, Chennai, Kolkata, Ahmedabad
A12: Listings at renewal risk (of 60) | B12: 5 | C12: Section 7
A13: Peak ordering day | B13: Saturday | C13: Tuesday softest
A14: Leading device | B14: Android App | C14: =TEXT('Device Mix'!C5,"0%")&" of orders" -> 49% of orders
A15: Highest-return category | B15: Makeup | C15: ~9.8% returned; lowest is Wellness & Nutrition ~3.5%
A16: Deepest Nykaa Prive adoption | B16: Mumbai | C16: 40%; leanest is Kolkata 14%
A17: Nykaa Prive share of GMV | B17: =Membership!D6 -> 0.61 | C17: Section 6.7
A18: Top revenue category | B18: =INDEX(Category!A5:A14,MATCH(MAX(Category!C5:C14),Category!C5:C14,0)) -> Luxury Beauty | C18: Luxury Beauty

Sheet All Data
A1: All Data - every table stacked on one sheet (live links to the individual sheets)
A3: Summary
A4: =Summary!A4 -> Metric | B4: =Summary!B4 -> Value | C4: =Summary!C4 -> Note
A5: =Summary!A5 -> Total orders - sum of categories | B5: =Summary!B5 -> 6881215 | C5: =Summary!C5 -> Report headline says ~6.8M
A6: =Summary!A6 -> Total orders - sum of devices | B6: =Summary!B6 -> 6835047 | C6: =Summary!C6 -> Differs slightly from category total
A7: =Summary!A7 -> Total GMV (INR Cr) - membership split | B7: =Summary!B7 -> 495.00848 | C7: =Summary!C7 -> Report headline: ~Rs. 495 Cr
A8: =Summary!A8 -> Total revenue (INR Cr) - category table | B8: =Summary!B8 -> 648.38623 | C8: =Summary!C8 -> Does NOT match 495 Cr headline - see Notes
A9: =Summary!A9 -> Average product rating (out of 5) | B9: =Summary!B9 -> 4.01 | C9: =Summary!C9 -> Section 5
A10: =Summary!A10 -> Top single-day product | B10: =Summary!B10 -> Nykaa Cosmetics Face Mist | C10: =Summary!C10 -> 34,399 orders
A11: =Summary!A11 -> Cities tracked | B11: =Summary!B11 -> 8 | C11: =Summary!C11 -> Bangalore, Delhi NCR, Mumbai, Hyderabad, Pune, Chennai, Kolkata, Ahmedabad
A12: =Summary!A12 -> Listings at renewal risk (of 60) | B12: =Summary!B12 -> 5 | C12: =Summary!C12 -> Section 7
A13: =Summary!A13 -> Peak ordering day | B13: =Summary!B13 -> Saturday | C13: =Summary!C13 -> Tuesday softest
A14: =Summary!A14 -> Leading device | B14: =Summary!B14 -> Android App | C14: =Summary!C14 -> 49% of orders
A15: =Summary!A15 -> Highest-return category | B15: =Summary!B15 -> Makeup | C15: =Summary!C15 -> ~9.8% returned; lowest is Wellness & Nutrition ~3.5%
... A18: =Summary!A18 -> Top revenue category | B18: =Summary!B18 -> Luxury Beauty | C18: =Summary!C18 -> Luxury Beauty
A21: Category
A22: =Category!A4 -> Category | B22: =Category!B4 -> Orders (30-day) | C22: =Category!C4 -> Revenue (INR) | D22: =Category!D4 -> Revenue (INR Cr) | E22: =Category!E4 -> Share of Orders | F22: =Category!F4 -> Share of Revenue | G22: =Category!G4 -> Revenue per Order (INR)
A23: =Category!A5 -> Luxury Beauty | B23: =Category!B5 -> 652909 | C23: =Category!C5 -> 1566981600 | D23: =Category!D5 -> 156.69816 | E23: =Category!E5 -> 0.094882808 | F23: =Category!F5 -> 0.2416741 | G23: =Category!G5 -> 2400
A24: =Category!A6 -> Fragrance | B24: =Category!B6 -> 747580 | C24: =Category!C6 -> 1083991000 | D24: =Category!D6 -> 108.3991 | E24: =Category!E6 -> 0.1086407 | F24: =Category!F6 -> 0.16718292 | G24: =Category!G6 -> 1450
A25: =Category!A7 -> Appliances & Tools | B25: =Category!B7 -> 391521 | C25: =Category!C7 -> 724313850 | D25: =Category!D7 -> 72.431385 | E25: =Category!E7 -> 0.056897074 | F25: =Category!F7 -> 0.11171025 | G25: =Category!G7 -> 1850
A26: =Category!A8 -> Baby Care | B26: =Category!B8 -> 1066865 | C26: =Category!C8 -> 650787650 | D26: =Category!D8 -> 65.078765 | E26: =Category!E8 -> 0.15504021 | F26: =Category!F8 -> 0.10037037 | G26: =Category!G8 -> 610
A27: =Category!A9 -> Wellness & Nutrition | B27: =Category!B9 -> 870672 | C27: =Category!C9 -> 600763680 | D27: =Category!D9 -> 60.076368 | E27: =Category!E9 -> 0.12652882 | F27: =Category!F9 -> 0.092655219 | G27: =Category!G9 -> 690
A28: =Category!A10 -> Bath & Body | B28: =Category!B10 -> 1212795 | C28: =Category!C10 -> 582141600 | D28: =Category!D10 -> 58.21416 | E28: =Category!E10 -> 0.17624722 | F28: =Category!F10 -> 0.089783153 | G28: =Category!G10 -> 480
A29: =Category!A11 -> Makeup | B29: =Category!B11 -> 683246 | C29: =Category!C11 -> 444109900 | D29: =Category!D11 -> 44.41099 | E29: =Category!E11 -> 0.099291477 | F29: =Category!F11 -> 0.068494653 | G29: =Category!G11 -> 650
A30: =Category!A12 -> Skincare | B30: =Category!B12 -> 569356 | C30: =Category!C12 -> 444097680 | D30: =Category!D12 -> 44.409768 | E30: =Category!E12 -> 0.082740621 | F30: =Category!F12 -> 0.068492769 | G30: =Category!G12 -> 780
A31: =Category!A13 -> Men's Grooming | B31: =Category!B13 -> 425920 | C31: =Category!C13 -> 251292800 | D31: =Category!D13 -> 25.12928 | E31: =Category!E13 -> 0.061896046 | F31: =Category!F13 -> 0.038756653 | G31: =Category!G13 -> 590
A32: =Category!A14 -> Haircare | B32: =Category!B14 -> 260351 | C32: =Category!C14 -> 135382520 | D32: =Category!D14 -> 13.538252 | E32: =Category!E14 -> 0.037835033 | F32: =Category!F14 -> 0.020879919 | G32: =Category!G14 -> 520
A33: =Category!A15 -> Total | B33: =Category!B15 -> 6881215 | C33: =Category!C15 -> 6483862280 | D33: =Category!D15 -> 648.38623 | E33: =Category!E15 -> 1 | F33: =Category!F15 -> 1 | G33: =Category!G15 -> 942.25544
A36: Device Mix
A37: ='Device Mix'!A4 -> Device / Platform | B37: ='Device Mix'!B4 -> Orders | C37: ='Device Mix'!C4 -> Share of Orders (calc) | D37: ='Device Mix'!D4 -> Share Reported in Report
A38: ='Device Mix'!A5 -> Android App | B38: ='Device Mix'!B5 -> 3349174 | C38: ='Device Mix'!C5 -> 0.49000014 | D38: ='Device Mix'!D5 -> 0.49
A39: ='Device Mix'!A6 -> iOS App | B39: ='Device Mix'!B6 -> 1845463 | C39: ='Device Mix'!C6 -> 0.27000005 | D39: ='Device Mix'!D6 -> 0.27
A40: ='Device Mix'!A7 -> Mobile Web | B40: ='Device Mix'!B7 -> 1025257 | C40: ='Device Mix'!C7 -> 0.14999999 | D40: ='Device Mix'!D7 -> 0.15
A41: ='Device Mix'!A8 -> Desktop Web | B41: ='Device Mix'!B8 -> 478453 | C41: ='Device Mix'!C8 -> 0.069999958 | D41: ='Device Mix'!D8 -> 0.07
A42: ='Device Mix'!A9 -> WhatsApp Shopping | B42: ='Device Mix'!B9 -> 136700 | C42: ='Device Mix'!C9 -> 0.019999862 | D42: ='Device Mix'!D9 -> 0.02
A43: ='Device Mix'!A10 -> Total | B43: ='Device Mix'!B10 -> 6835047 | C43: ='Device Mix'!C10 -> 1 | D43: ='Device Mix'!D10 -> 1
A46: Membership
A47: =Membership!A4 -> Membership Tier | B47: =Membership!B4 -> GMV (INR) | C47: =Membership!C4 -> GMV (INR Cr) | D47: =Membership!D4 -> GMV Share (calc) | E47: =Membership!E4 -> GMV Share Reported
A48: =Membership!A5 -> Non-Member | B48: =Membership!B5 -> 1930533091 | C48: =Membership!C5 -> 193.05331 | D48: =Membership!D5 -> 0.39 | E48: =Membership!E5 -> 0.39
A49: =Membership!A6 -> Nykaa Prive | B49: =Membership!B6 -> 3019551758 | C49: =Membership!C6 -> 301.95518 | D49: =Membership!D6 -> 0.61 | E49: =Membership!E6 -> 0.61
...

Sheet Category
A1: Category Performance (30 days)
A2: Source: Nykaa Descriptive Analytics Report (simulated data). Blue = value taken from report; black = formula. Report Appendix B / Fig 8-9.
A4: Category | B4: Orders (30-day) | C4: Revenue (INR) | D4: Revenue (INR Cr) | E4: Share of Orders | F4: Share of Revenue | G4: Revenue per Order (INR)
A5: Luxury Beauty | B5: 652909 | C5: 1566981600 | D5: =C5/10000000 -> 156.69816 | E5: =B5/$B$15 -> 0.094882808 | F5: =C5/$C$15 -> 0.2416741 | G5: =C5/B5 -> 2400
A6: Fragrance | B6: 747580 | C6: 1083991000 | D6: =C6/10000000 -> 108.3991 | E6: =B6/$B$15 -> 0.1086407 | F6: =C6/$C$15 -> 0.16718292 | G6: =C6/B6 -> 1450
A7: Appliances & Tools | B7: 391521 | C7: 724313850 | D7: =C7/10000000 -> 72.431385 | E7: =B7/$B$15 -> 0.056897074 | F7: =C7/$C$15 -> 0.11171025 | G7: =C7/B7 -> 1850
A8: Baby Care | B8: 1066865 | C8: 650787650 | D8: =C8/10000000 -> 65.078765 | E8: =B8/$B$15 -> 0.15504021 | F8: =C8/$C$15 -> 0.10037037 | G8: =C8/B8 -> 610
A9: Wellness & Nutrition | B9: 870672 | C9: 600763680 | D9: =C9/10000000 -> 60.076368 | E9: =B9/$B$15 -> 0.12652882 | F9: =C9/$C$15 -> 0.092655219 | G9: =C9/B9 -> 690
A10: Bath & Body | B10: 1212795 | C10: 582141600 | D10: =C10/10000000 -> 58.21416 | E10: =B10/$B$15 -> 0.17624722 | F10: =C10/$C$15 -> 0.089783153 | G10: =C10/B10 -> 480
A11: Makeup | B11: 683246 | C11: 444109900 | D11: =C11/10000000 -> 44.41099 | E11: =B11/$B$15 -> 0.099291477 | F11: =C11/$C$15 -> 0.068494653 | G11: =C11/B11 -> 650
A12: Skincare | B12: 569356 | C12: 444097680 | D12: =C12/10000000 -> 44.409768 | E12: =B12/$B$15 -> 0.082740621 | F12: =C12/$C$15 -> 0.068492769 | G12: =C12/B12 -> 780
A13: Men's Grooming | B13: 425920 | C13: 251292800 | D13: =C13/10000000 -> 25.12928 | E13: =B13/$B$15 -> 0.061896046 | F13: =C13/$C$15 -> 0.038756653 | G13: =C13/B13 -> 590
A14: Haircare | B14: 260351 | C14: 135382520 | D14: =C14/10000000 -> 13.538252 | E14: =B14/$B$15 -> 0.037835033 | F14: =C14/$C$15 -> 0.020879919 | G14: =C14/B14 -> 520
A15: Total | B15: =SUM(B5:B14) -> 6881215 | C15: =SUM(C5:C14) -> 6483862280 | D15: =SUM(D5:D14) -> 648.38623 | E15: =SUM(E5:E14) -> 1 | F15: =SUM(F5:F14) -> 1 | G15: =C15/B15 -> 942.25544
A17: Revenue per Order = revenue / orders (proxy for average order value).

Sheet Device Mix
A1: Device / Platform Mix
A2: Source: Nykaa Descriptive Analytics Report (simulated data). Blue = value taken from report; black = formula. Report Section 6.4.
A4: Device / Platform | B4: Orders | C4: Share of Orders (calc) | D4: Share Reported in Report
A5: Android App | B5: 3349174 | C5: =B5/$B$10 -> 0.49000014 | D5: 0.49
A6: iOS App | B6: 1845463 | C6: =B6/$B$10 -> 0.27000005 | D6: 0.27
A7: Mobile Web | B7: 1025257 | C7: =B7/$B$10 -> 0.14999999 | D7: 0.15
A8: Desktop Web | B8: 478453 | C8: =B8/$B$10 -> 0.069999958 | D8: 0.07
A9: WhatsApp Shopping | B9: 136700 | C9: =B9/$B$10 -> 0.019999862 | D9: 0.02
A10: Total | B10: =SUM(B5:B9) -> 6835047 | C10: =SUM(C5:C9) -> 1 | D10: =SUM(D5:D9) -> 1

Sheet Membership
A1: Revenue by Membership Tier
A2: Source: Nykaa Descriptive Analytics Report (simulated data). Blue = value taken from report; black = formula. Report Section 6.7.
A4: Membership Tier | B4: GMV (INR) | C4: GMV (INR Cr) | D4: GMV Share (calc) | E4: GMV Share Reported
A5: Non-Member | B5: 1930533091 | C5: =B5/10000000 -> 193.05331 | D5: =B5/$B$7 -> 0.39 | E5: 0.39
A6: Nykaa Prive | B6: 3019551758 | C6: =B6/10000000 -> 301.95518 | D6: =B6/$B$7 -> 0.61 | E6: 0.61
A7: Total | B7: =SUM(B5:B6) -> 4950084849 | C7: =SUM(C5:C6) -> 495.00848 | D7: =SUM(D5:D6) -> 1 | E7: =SUM(E5:E6) -> 1

Sheet City
A1: City-Wise Demand & Nykaa Prive Adoption
A2: Order counts are APPROXIMATE values read off Fig 7 (report gives no table). Prive adoption % is from Fig 13.
A4: City | B4: Orders (Millions, approx.) | C4: Share of Orders | D4: Nykaa Prive Adoption
A5: Mumbai | B5: 1.65 | C5: =B5/$B$13 -> 0.23982558 | D5: 0.4
A6: Hyderabad | B6: 1.39 | C6: =B6/$B$13 -> 0.20203488 | D6: 0.25
A7: Chennai | B7: 1.04 | C7: =B7/$B$13 -> 0.15116279 | D7: 0.22
A8: Pune | B8: 0.86 | C8: =B8/$B$13 -> 0.125 | D8: 0.27
A9: Bangalore | B9: 0.7 | C9: =B9/$B$13 -> 0.10174419 | D9: 0.36
A10: Kolkata | B10: 0.65 | C10: =B10/$B$13 -> 0.094476744 | D10: 0.14
A11: Delhi NCR | B11: 0.39 | C11: =B11/$B$13 -> 0.056686047 | D11: 0.38
A12: Ahmedabad | B12: 0.2 | C12: =B12/$B$13 -> 0.029069767 | D12: 0.16
A13: Total | B13: =SUM(B5:B12) -> 6.88 | C13: =SUM(C5:C12) -> 1 | D13: =AVERAGE(D5:D12) -> 0.2725
A14: Total row: Prive adoption shown is a simple (unweighted) average of cities.

Sheet Top Products
A1: Most-Ordered Products - Most Recent Day
A2: Orders: #1 exact (34,399 per report); #2-10 approximate, read off Fig 3. New customers from Fig 4 / table in Section 4.1 (top 6 exact).
A4: Rank | B4: Product | C4: Orders (most recent day) | D4: Orders Basis | E4: Share of Top-10 Orders | F4: New Customers | G4: Category (as listed in report)
A5: 1 | B5: Nykaa Cosmetics Face Mist | C5: 34399 | D5: Exact | E5: =C5/$C$15 -> 0.28358849 | F5: 5581 | G5: Baby Care
A6: 2 | B6: L'Oreal Paris Hydrating Face Wash | C6: 13700 | D6: Approx. | E6: =C6/$C$15 -> 0.11294405 | F6: 2791 | G6: Luxury Beauty
A7: 3 | B7: Maybelline Beard Oil | C7: 13700 | D7: Approx. | E7: =C7/$C$15 -> 0.11294405 | F7: 4908 | G7: Fragrance
A8: 4 | B8: Forest Essentials Eyeliner | C8: 12000 | D8: Approx. | E8: =C8/$C$15 -> 0.098929093 | F8: 3701 | G8: Bath & Body
A9: 5 | B9: Kay Beauty Vitamin C Serum | C9: 10900 | D9: Approx. | E9: =C9/$C$15 -> 0.089860592 | F9: 2540 | G9: Wellness & Nutrition
A10: 6 | B10: Minimalist Hair Oil | C10: 9500 | D10: Approx. | E10: =C10/$C$15 -> 0.078318865 | F10: n/a | G10: n/a
A11: 7 | B11: Colorbar Face Mist | C11: 7400 | D11: Approx. | E11: =C11/$C$15 -> 0.061006274 | F11: n/a | G11: n/a
A12: 8 | B12: Faces Canada Matte Lipstick | C12: 7100 | D12: Approx. | E12: =C12/$C$15 -> 0.058533046 | F12: n/a | G12: n/a
A13: 9 | B13: Kay Beauty Eau de Parfum | C13: 6700 | D13: Approx. | E13: =C13/$C$15 -> 0.05523541 | F13: 2533 | G13: Wellness & Nutrition
A14: 10 | B14: MyGlamm Under Eye Cream | C14: 5900 | D14: Approx. | E14: =C14/$C$15 -> 0.048640137 | F14: n/a | G14: n/a
B15: Top-10 total | C15: =SUM(C5:C14) -> 121299 | E15: =SUM(E5:E14) -> 1
A17: Other products in the New Customers top 10 (Fig 4, no values given): Dot & Key Lip Balm.
A18: Category labels are exactly as printed in the report; several look mismatched (e.g. Face Mist under Baby Care).

Sheet Ratings & Quality
A1: Rating Risk
A2: Source: Nykaa Descriptive Analytics Report (simulated data). Blue = value taken from report; black = formula. Sections 5.1-5.2. Average rating across all product-days: 4.01 / 5.
A4: Product | B4: Monthly Orders | C4: Current Rating | D4: Risk Threshold | E4: Below Threshold? | F4: Declining 7-day Trend? | G4: Product ID
A5: Sugar Hair Styling Cream | B5: 186510 | C5: 2.54 | D5: 3.5 | E5: =IF(C5<D5,"High risk","OK") -> High risk | F5: Yes | G5: NYKA-4026
A6: Dot & Key Lip Balm | B6: 148671 | C6: 2.72 | D6: 3.5 | E6: =IF(C6<D6,"High risk","OK") -> High risk | F6: Yes | G6: NYKA-4015
A7: L'Oreal Paris Kajal | B7: 90990 | C7: 3.06 | D7: 3.5 | E7: =IF(C7<D7,"High risk","OK") -> High risk | F7: Yes | G7: NYKA-4014
A8: Forest Essentials Eyeliner | B8: 291142 | C8: 3.44 | D8: 3.5 | E8: =IF(C8<D8,"High risk","OK") -> High risk | F8: No | G8: n/a
A10: Declining-rating products (6, Fig 6)
A11: Product ID | B11: Product
A12: NYKA-4014 | B12: L'Oreal Paris Kajal
A13: NYKA-4015 | B13: Dot & Key Lip Balm
A14: NYKA-4026 | B14: Sugar Hair Styling Cream
A15: NYKA-4031 | B15: Re'Equil Shampoo
A16: NYKA-4048 | B16: MyGlamm Kajal
A17: NYKA-4052 | B17: Lakme Hair Oil
A19: Risk threshold 3.5 is the report's sub-3.5 definition (blue input - editable).

Sheet Contract Renewal
A1: Brand Listings Closest to Contract Renewal
A2: Days remaining are APPROXIMATE values read off Fig 16. Status counts: 55 Active / 5 Renewal Due Soon / 0 Under Quality Review (Fig 15).
A4: Product Listing | B4: Est. Days to Renewal | C4: Renewal Trigger (days) | D4: Status
A5: Sugar Hair Styling Cream | B5: 11 | C5: 30 | D5: =IF(B5<C5,"Renewal Due Soon","Active") -> Renewal Due Soon
A6: MyGlamm Kajal | B6: 20 | C6: 30 | D6: =IF(B6<C6,"Renewal Due Soon","Active") -> Renewal Due Soon
A7: Biotique Kajal | B7: 24 | C7: 30 | D7: =IF(B7<C7,"Renewal Due Soon","Active") -> Renewal Due Soon
A8: L'Oreal Paris BB Cream | B8: 24 | C8: 30 | D8: =IF(B8<C8,"Renewal Due Soon","Active") -> Renewal Due Soon
A9: Faces Canada Matte Lipstick | B9: 29 | C9: 30 | D9: =IF(B9<C9,"Renewal Due Soon","Active") -> Renewal Due Soon
A10: Nivea Beard Oil | B10: 44 | C10: 30 | D10: =IF(B10<C10,"Renewal Due Soon","Active") -> Active
A11: Colorbar Kajal Pencil | B11: 48 | C11: 30 | D11: =IF(B11<C11,"Renewal Due Soon","Active") -> Active
A12: L'Oreal Paris Kajal | B12: 60 | C12: 30 | D12: =IF(B12<C12,"Renewal Due Soon","Active") -> Active
A13: WOW Skin Science BB Cream | B13: 61 | C13: 30 | D13: =IF(B13<C13,"Renewal Due Soon","Active") -> Active
A14: MyGlamm Hair Mask | B14: 63 | C14: 30 | D14: =IF(B14<C14,"Renewal Due Soon","Active") -> Active
A16: Listings due soon (of 10 shown) | B16: =COUNTIF(D5:D14,"Renewal Due Soon") -> 5

Sheet Notes
A1: Data Notes & Report Inconsistencies
A3: 1. All data is synthetic (per the report's Appendix A); no real Nykaa data was used.
A4: 2. Daily orders (Fig 1), daily revenue (Fig 2) and the rating trend lines (Fig 6) exist only as charts in the report with no underlying numbers, so they are not reproduced here.
A5: 3. Values labelled 'approx.' (city orders, top-10 orders #2-10, renewal days) were estimated by eye from charts - treat as indicative only.
A6: 4. Inconsistency: the category revenue table totals ~Rs. 648 Cr, but the headline GMV and membership split total ~Rs. 495 Cr.
A7: 5. Inconsistency: category orders total ~6.88M vs. device-mix total ~6.84M (headline ~6.8M).
A8: 6. Inconsistency: Section 6.2 insight names Skincare and Makeup as the volume backbone, but the table shows Bath & Body and Baby Care with the most orders.
A9: 7. Inconsistency: Section 6 text says city demand was 'fairly balanced' while the chart shows Mumbai at ~8x Ahmedabad.
A10: 8. Product-to-category mapping in Section 4.1 looks mismatched (e.g. Face Mist under Baby Care, Eyeliner under Bath & Body), likely a simulation artifact.
